Problem at: /home/ludvik/Desktop/rs_sb3/local_multi.py 88 run_training
Problem at: /home/ludvik/Desktop/rs_sb3/local_multi.py 88 run_training
Problem at: /home/ludvik/Desktop/rs_sb3/local_multi.py 88 run_training
[34m[1mwandb[39m[22m: Currently logged in as: [33mludvikka[39m (use `wandb login --relogin` to force relogin)
Traceback (most recent call last):
  File "/home/ludvik/anaconda3/envs/RS_SB3_test/lib/python3.8/site-packages/wandb/sdk/wandb_init.py", line 954, in init
    run = wi.init()
  File "/home/ludvik/anaconda3/envs/RS_SB3_test/lib/python3.8/site-packages/wandb/sdk/wandb_init.py", line 499, in init
    backend.ensure_launched()
  File "/home/ludvik/anaconda3/envs/RS_SB3_test/lib/python3.8/site-packages/wandb/sdk/backend/backend.py", line 222, in ensure_launched
    self.wandb_process.start()
  File "/home/ludvik/anaconda3/envs/RS_SB3_test/lib/python3.8/multiprocessing/process.py", line 121, in start
    self._popen = self._Popen(self)
  File "/home/ludvik/anaconda3/envs/RS_SB3_test/lib/python3.8/multiprocessing/context.py", line 284, in _Popen
    return Popen(process_obj)
  File "/home/ludvik/anaconda3/envs/RS_SB3_test/lib/python3.8/multiprocessing/popen_spawn_posix.py", line 32, in __init__
    super().__init__(process_obj)
  File "/home/ludvik/anaconda3/envs/RS_SB3_test/lib/python3.8/multiprocessing/popen_fork.py", line 19, in __init__
    self._launch(process_obj)
  File "/home/ludvik/anaconda3/envs/RS_SB3_test/lib/python3.8/multiprocessing/popen_spawn_posix.py", line 42, in _launch
    prep_data = spawn.get_preparation_data(process_obj._name)
  File "/home/ludvik/anaconda3/envs/RS_SB3_test/lib/python3.8/multiprocessing/spawn.py", line 154, in get_preparation_data
    _check_not_importing_main()
  File "/home/ludvik/anaconda3/envs/RS_SB3_test/lib/python3.8/multiprocessing/spawn.py", line 134, in _check_not_importing_main
    raise RuntimeError('''
RuntimeError:
        An attempt has been made to start a new process before the
        current process has finished its bootstrapping phase.
        This probably means that you are not using fork to start your
        child processes and you have forgotten to use the proper idiom
        in the main module:
            if __name__ == '__main__':
                freeze_support()
                ...
        The "freeze_support()" line can be omitted if the program
        is not going to be frozen to produce an executable.
[34m[1mwandb[39m[22m: Currently logged in as: [33mludvikka[39m (use `wandb login --relogin` to force relogin)
Traceback (most recent call last):
  File "/home/ludvik/anaconda3/envs/RS_SB3_test/lib/python3.8/site-packages/wandb/sdk/wandb_init.py", line 954, in init
    run = wi.init()
  File "/home/ludvik/anaconda3/envs/RS_SB3_test/lib/python3.8/site-packages/wandb/sdk/wandb_init.py", line 499, in init
    backend.ensure_launched()
  File "/home/ludvik/anaconda3/envs/RS_SB3_test/lib/python3.8/site-packages/wandb/sdk/backend/backend.py", line 222, in ensure_launched
    self.wandb_process.start()
  File "/home/ludvik/anaconda3/envs/RS_SB3_test/lib/python3.8/multiprocessing/process.py", line 121, in start
    self._popen = self._Popen(self)
  File "/home/ludvik/anaconda3/envs/RS_SB3_test/lib/python3.8/multiprocessing/context.py", line 284, in _Popen
    return Popen(process_obj)
  File "/home/ludvik/anaconda3/envs/RS_SB3_test/lib/python3.8/multiprocessing/popen_spawn_posix.py", line 32, in __init__
    super().__init__(process_obj)
  File "/home/ludvik/anaconda3/envs/RS_SB3_test/lib/python3.8/multiprocessing/popen_fork.py", line 19, in __init__
    self._launch(process_obj)
  File "/home/ludvik/anaconda3/envs/RS_SB3_test/lib/python3.8/multiprocessing/popen_spawn_posix.py", line 42, in _launch
    prep_data = spawn.get_preparation_data(process_obj._name)
  File "/home/ludvik/anaconda3/envs/RS_SB3_test/lib/python3.8/multiprocessing/spawn.py", line 154, in get_preparation_data
    _check_not_importing_main()
  File "/home/ludvik/anaconda3/envs/RS_SB3_test/lib/python3.8/multiprocessing/spawn.py", line 134, in _check_not_importing_main
    raise RuntimeError('''
RuntimeError:
        An attempt has been made to start a new process before the
        current process has finished its bootstrapping phase.
        This probably means that you are not using fork to start your
        child processes and you have forgotten to use the proper idiom
        in the main module:
            if __name__ == '__main__':
                freeze_support()
                ...
        The "freeze_support()" line can be omitted if the program
        is not going to be frozen to produce an executable.
[34m[1mwandb[39m[22m: Currently logged in as: [33mludvikka[39m (use `wandb login --relogin` to force relogin)
Traceback (most recent call last):
  File "/home/ludvik/anaconda3/envs/RS_SB3_test/lib/python3.8/site-packages/wandb/sdk/wandb_init.py", line 954, in init
    run = wi.init()
  File "/home/ludvik/anaconda3/envs/RS_SB3_test/lib/python3.8/site-packages/wandb/sdk/wandb_init.py", line 499, in init
    backend.ensure_launched()
  File "/home/ludvik/anaconda3/envs/RS_SB3_test/lib/python3.8/site-packages/wandb/sdk/backend/backend.py", line 222, in ensure_launched
    self.wandb_process.start()
  File "/home/ludvik/anaconda3/envs/RS_SB3_test/lib/python3.8/multiprocessing/process.py", line 121, in start
    self._popen = self._Popen(self)
  File "/home/ludvik/anaconda3/envs/RS_SB3_test/lib/python3.8/multiprocessing/context.py", line 284, in _Popen
    return Popen(process_obj)
  File "/home/ludvik/anaconda3/envs/RS_SB3_test/lib/python3.8/multiprocessing/popen_spawn_posix.py", line 32, in __init__
    super().__init__(process_obj)
  File "/home/ludvik/anaconda3/envs/RS_SB3_test/lib/python3.8/multiprocessing/popen_fork.py", line 19, in __init__
    self._launch(process_obj)
  File "/home/ludvik/anaconda3/envs/RS_SB3_test/lib/python3.8/multiprocessing/popen_spawn_posix.py", line 42, in _launch
    prep_data = spawn.get_preparation_data(process_obj._name)
  File "/home/ludvik/anaconda3/envs/RS_SB3_test/lib/python3.8/multiprocessing/spawn.py", line 154, in get_preparation_data
    _check_not_importing_main()
  File "/home/ludvik/anaconda3/envs/RS_SB3_test/lib/python3.8/multiprocessing/spawn.py", line 134, in _check_not_importing_main
    raise RuntimeError('''
RuntimeError:
        An attempt has been made to start a new process before the
        current process has finished its bootstrapping phase.
        This probably means that you are not using fork to start your
        child processes and you have forgotten to use the proper idiom
        in the main module:
            if __name__ == '__main__':
                freeze_support()
                ...
        The "freeze_support()" line can be omitted if the program
        is not going to be frozen to produce an executable.
[34m[1mwandb[39m[22m: [32m[41mERROR[39m[49m Abnormal program exit
Traceback (most recent call last):
  File "/home/ludvik/anaconda3/envs/RS_SB3_test/lib/python3.8/site-packages/wandb/sdk/wandb_init.py", line 954, in init
    run = wi.init()
  File "/home/ludvik/anaconda3/envs/RS_SB3_test/lib/python3.8/site-packages/wandb/sdk/wandb_init.py", line 499, in init
    backend.ensure_launched()
  File "/home/ludvik/anaconda3/envs/RS_SB3_test/lib/python3.8/site-packages/wandb/sdk/backend/backend.py", line 222, in ensure_launched
    self.wandb_process.start()
  File "/home/ludvik/anaconda3/envs/RS_SB3_test/lib/python3.8/multiprocessing/process.py", line 121, in start
    self._popen = self._Popen(self)
  File "/home/ludvik/anaconda3/envs/RS_SB3_test/lib/python3.8/multiprocessing/context.py", line 284, in _Popen
    return Popen(process_obj)
  File "/home/ludvik/anaconda3/envs/RS_SB3_test/lib/python3.8/multiprocessing/popen_spawn_posix.py", line 32, in __init__
    super().__init__(process_obj)
  File "/home/ludvik/anaconda3/envs/RS_SB3_test/lib/python3.8/multiprocessing/popen_fork.py", line 19, in __init__
    self._launch(process_obj)
  File "/home/ludvik/anaconda3/envs/RS_SB3_test/lib/python3.8/multiprocessing/popen_spawn_posix.py", line 42, in _launch
    prep_data = spawn.get_preparation_data(process_obj._name)
  File "/home/ludvik/anaconda3/envs/RS_SB3_test/lib/python3.8/multiprocessing/spawn.py", line 154, in get_preparation_data
    _check_not_importing_main()
  File "/home/ludvik/anaconda3/envs/RS_SB3_test/lib/python3.8/multiprocessing/spawn.py", line 134, in _check_not_importing_main
    raise RuntimeError('''
RuntimeError:
        An attempt has been made to start a new process before the
        current process has finished its bootstrapping phase.
        This probably means that you are not using fork to start your
        child processes and you have forgotten to use the proper idiom
        in the main module:
            if __name__ == '__main__':
                freeze_support()
                ...
        The "freeze_support()" line can be omitted if the program
        is not going to be frozen to produce an executable.
The above exception was the direct cause of the following exception:
Traceback (most recent call last):
  File "/home/ludvik/anaconda3/envs/RS_SB3_test/lib/python3.8/multiprocessing/forkserver.py", line 280, in main
    code = _serve_one(child_r, fds,
  File "/home/ludvik/anaconda3/envs/RS_SB3_test/lib/python3.8/multiprocessing/forkserver.py", line 319, in _serve_one
    code = spawn._main(child_r, parent_sentinel)
  File "/home/ludvik/anaconda3/envs/RS_SB3_test/lib/python3.8/multiprocessing/spawn.py", line 125, in _main
    prepare(preparation_data)
  File "/home/ludvik/anaconda3/envs/RS_SB3_test/lib/python3.8/multiprocessing/spawn.py", line 236, in prepare
    _fixup_main_from_path(data['init_main_from_path'])
  File "/home/ludvik/anaconda3/envs/RS_SB3_test/lib/python3.8/multiprocessing/spawn.py", line 287, in _fixup_main_from_path
    main_content = runpy.run_path(main_path,
  File "/home/ludvik/anaconda3/envs/RS_SB3_test/lib/python3.8/runpy.py", line 265, in run_path
    return _run_module_code(code, init_globals, run_name,
  File "/home/ludvik/anaconda3/envs/RS_SB3_test/lib/python3.8/runpy.py", line 97, in _run_module_code
    _run_code(code, mod_globals, init_globals,
  File "/home/ludvik/anaconda3/envs/RS_SB3_test/lib/python3.8/runpy.py", line 87, in _run_code
    exec(code, run_globals)
  File "/home/ludvik/Desktop/rs_sb3/run_multiple_tests.py", line 4, in <module>
    run_training(cfg)
  File "/home/ludvik/Desktop/rs_sb3/local_multi.py", line 88, in run_training
    run = wandb.init(project=cfg.WANDB.NAME,
  File "/home/ludvik/anaconda3/envs/RS_SB3_test/lib/python3.8/site-packages/wandb/sdk/wandb_init.py", line 992, in init
    six.raise_from(Exception("problem"), error_seen)
  File "<string>", line 3, in raise_from
Exception: problem
Traceback (most recent call last):
  File "run_multiple_tests.py", line 4, in <module>
    run_training(cfg)
  File "/home/ludvik/Desktop/rs_sb3/local_multi.py", line 94, in run_training
    vec_gym_env = SubprocVecEnv([make_env(i , cfg.ENV) for i in range(num_cpu)])
  File "/home/ludvik/anaconda3/envs/RS_SB3_test/lib/python3.8/site-packages/stable_baselines3/common/vec_env/subproc_vec_env.py", line 111, in __init__
    observation_space, action_space = self.remotes[0].recv()
  File "/home/ludvik/anaconda3/envs/RS_SB3_test/lib/python3.8/multiprocessing/connection.py", line 250, in recv
    buf = self._recv_bytes()
  File "/home/ludvik/anaconda3/envs/RS_SB3_test/lib/python3.8/multiprocessing/connection.py", line 414, in _recv_bytes
    buf = self._recv(4)
  File "/home/ludvik/anaconda3/envs/RS_SB3_test/lib/python3.8/multiprocessing/connection.py", line 379, in _recv
    chunk = read(handle, remaining)
ConnectionResetError: [Errno 104] Connection reset by peer
[34m[1mwandb[39m[22m: [32m[41mERROR[39m[49m Abnormal program exit
Traceback (most recent call last):
  File "/home/ludvik/anaconda3/envs/RS_SB3_test/lib/python3.8/site-packages/wandb/sdk/wandb_init.py", line 954, in init
    run = wi.init()
  File "/home/ludvik/anaconda3/envs/RS_SB3_test/lib/python3.8/site-packages/wandb/sdk/wandb_init.py", line 499, in init
    backend.ensure_launched()
  File "/home/ludvik/anaconda3/envs/RS_SB3_test/lib/python3.8/site-packages/wandb/sdk/backend/backend.py", line 222, in ensure_launched
    self.wandb_process.start()
  File "/home/ludvik/anaconda3/envs/RS_SB3_test/lib/python3.8/multiprocessing/process.py", line 121, in start
    self._popen = self._Popen(self)
  File "/home/ludvik/anaconda3/envs/RS_SB3_test/lib/python3.8/multiprocessing/context.py", line 284, in _Popen
    return Popen(process_obj)
  File "/home/ludvik/anaconda3/envs/RS_SB3_test/lib/python3.8/multiprocessing/popen_spawn_posix.py", line 32, in __init__
    super().__init__(process_obj)
  File "/home/ludvik/anaconda3/envs/RS_SB3_test/lib/python3.8/multiprocessing/popen_fork.py", line 19, in __init__
    self._launch(process_obj)
  File "/home/ludvik/anaconda3/envs/RS_SB3_test/lib/python3.8/multiprocessing/popen_spawn_posix.py", line 42, in _launch
    prep_data = spawn.get_preparation_data(process_obj._name)
  File "/home/ludvik/anaconda3/envs/RS_SB3_test/lib/python3.8/multiprocessing/spawn.py", line 154, in get_preparation_data
    _check_not_importing_main()
  File "/home/ludvik/anaconda3/envs/RS_SB3_test/lib/python3.8/multiprocessing/spawn.py", line 134, in _check_not_importing_main
    raise RuntimeError('''
RuntimeError:
        An attempt has been made to start a new process before the
        current process has finished its bootstrapping phase.
        This probably means that you are not using fork to start your
        child processes and you have forgotten to use the proper idiom
        in the main module:
            if __name__ == '__main__':
                freeze_support()
                ...
        The "freeze_support()" line can be omitted if the program
        is not going to be frozen to produce an executable.
The above exception was the direct cause of the following exception:
Traceback (most recent call last):
  File "/home/ludvik/anaconda3/envs/RS_SB3_test/lib/python3.8/multiprocessing/forkserver.py", line 280, in main
    code = _serve_one(child_r, fds,
  File "/home/ludvik/anaconda3/envs/RS_SB3_test/lib/python3.8/multiprocessing/forkserver.py", line 319, in _serve_one
    code = spawn._main(child_r, parent_sentinel)
  File "/home/ludvik/anaconda3/envs/RS_SB3_test/lib/python3.8/multiprocessing/spawn.py", line 125, in _main
    prepare(preparation_data)
  File "/home/ludvik/anaconda3/envs/RS_SB3_test/lib/python3.8/multiprocessing/spawn.py", line 236, in prepare
    _fixup_main_from_path(data['init_main_from_path'])
  File "/home/ludvik/anaconda3/envs/RS_SB3_test/lib/python3.8/multiprocessing/spawn.py", line 287, in _fixup_main_from_path
    main_content = runpy.run_path(main_path,
  File "/home/ludvik/anaconda3/envs/RS_SB3_test/lib/python3.8/runpy.py", line 265, in run_path
    return _run_module_code(code, init_globals, run_name,
  File "/home/ludvik/anaconda3/envs/RS_SB3_test/lib/python3.8/runpy.py", line 97, in _run_module_code
    _run_code(code, mod_globals, init_globals,
  File "/home/ludvik/anaconda3/envs/RS_SB3_test/lib/python3.8/runpy.py", line 87, in _run_code
    exec(code, run_globals)
  File "/home/ludvik/Desktop/rs_sb3/run_multiple_tests.py", line 4, in <module>
    run_training(cfg)
  File "/home/ludvik/Desktop/rs_sb3/local_multi.py", line 88, in run_training
    run = wandb.init(project=cfg.WANDB.NAME,
  File "/home/ludvik/anaconda3/envs/RS_SB3_test/lib/python3.8/site-packages/wandb/sdk/wandb_init.py", line 992, in init
    six.raise_from(Exception("problem"), error_seen)
  File "<string>", line 3, in raise_from
Exception: problem
[34m[1mwandb[39m[22m: [32m[41mERROR[39m[49m Abnormal program exit
Traceback (most recent call last):
  File "/home/ludvik/anaconda3/envs/RS_SB3_test/lib/python3.8/site-packages/wandb/sdk/wandb_init.py", line 954, in init
    run = wi.init()
  File "/home/ludvik/anaconda3/envs/RS_SB3_test/lib/python3.8/site-packages/wandb/sdk/wandb_init.py", line 499, in init
    backend.ensure_launched()
  File "/home/ludvik/anaconda3/envs/RS_SB3_test/lib/python3.8/site-packages/wandb/sdk/backend/backend.py", line 222, in ensure_launched
    self.wandb_process.start()
  File "/home/ludvik/anaconda3/envs/RS_SB3_test/lib/python3.8/multiprocessing/process.py", line 121, in start
    self._popen = self._Popen(self)
  File "/home/ludvik/anaconda3/envs/RS_SB3_test/lib/python3.8/multiprocessing/context.py", line 284, in _Popen
    return Popen(process_obj)
  File "/home/ludvik/anaconda3/envs/RS_SB3_test/lib/python3.8/multiprocessing/popen_spawn_posix.py", line 32, in __init__
    super().__init__(process_obj)
  File "/home/ludvik/anaconda3/envs/RS_SB3_test/lib/python3.8/multiprocessing/popen_fork.py", line 19, in __init__
    self._launch(process_obj)
  File "/home/ludvik/anaconda3/envs/RS_SB3_test/lib/python3.8/multiprocessing/popen_spawn_posix.py", line 42, in _launch
    prep_data = spawn.get_preparation_data(process_obj._name)
  File "/home/ludvik/anaconda3/envs/RS_SB3_test/lib/python3.8/multiprocessing/spawn.py", line 154, in get_preparation_data
    _check_not_importing_main()
  File "/home/ludvik/anaconda3/envs/RS_SB3_test/lib/python3.8/multiprocessing/spawn.py", line 134, in _check_not_importing_main
    raise RuntimeError('''
RuntimeError:
        An attempt has been made to start a new process before the
        current process has finished its bootstrapping phase.
        This probably means that you are not using fork to start your
        child processes and you have forgotten to use the proper idiom
        in the main module:
            if __name__ == '__main__':
                freeze_support()
                ...
        The "freeze_support()" line can be omitted if the program
        is not going to be frozen to produce an executable.
The above exception was the direct cause of the following exception:
Traceback (most recent call last):
  File "/home/ludvik/anaconda3/envs/RS_SB3_test/lib/python3.8/multiprocessing/forkserver.py", line 280, in main
    code = _serve_one(child_r, fds,
  File "/home/ludvik/anaconda3/envs/RS_SB3_test/lib/python3.8/multiprocessing/forkserver.py", line 319, in _serve_one
    code = spawn._main(child_r, parent_sentinel)
  File "/home/ludvik/anaconda3/envs/RS_SB3_test/lib/python3.8/multiprocessing/spawn.py", line 125, in _main
    prepare(preparation_data)
  File "/home/ludvik/anaconda3/envs/RS_SB3_test/lib/python3.8/multiprocessing/spawn.py", line 236, in prepare
    _fixup_main_from_path(data['init_main_from_path'])
  File "/home/ludvik/anaconda3/envs/RS_SB3_test/lib/python3.8/multiprocessing/spawn.py", line 287, in _fixup_main_from_path
    main_content = runpy.run_path(main_path,
  File "/home/ludvik/anaconda3/envs/RS_SB3_test/lib/python3.8/runpy.py", line 265, in run_path
    return _run_module_code(code, init_globals, run_name,
  File "/home/ludvik/anaconda3/envs/RS_SB3_test/lib/python3.8/runpy.py", line 97, in _run_module_code
    _run_code(code, mod_globals, init_globals,
  File "/home/ludvik/anaconda3/envs/RS_SB3_test/lib/python3.8/runpy.py", line 87, in _run_code
    exec(code, run_globals)
  File "/home/ludvik/Desktop/rs_sb3/run_multiple_tests.py", line 4, in <module>
    run_training(cfg)
  File "/home/ludvik/Desktop/rs_sb3/local_multi.py", line 88, in run_training
    run = wandb.init(project=cfg.WANDB.NAME,
  File "/home/ludvik/anaconda3/envs/RS_SB3_test/lib/python3.8/site-packages/wandb/sdk/wandb_init.py", line 992, in init
    six.raise_from(Exception("problem"), error_seen)
  File "<string>", line 3, in raise_from
Exception: problem